<?xml version='1.0' encoding='utf-8'?>
<sdf version="1.6">
    <model name="submarine">
      <link name="body">
        <pose>0 0 0 1.57 0 1.2</pose>
        <inertial>
          <mass>6280</mass>
          <inertia>
            <ixx>1000</ixx>
            <ixy>0</ixy>
            <ixz>0</ixz>
            <iyy>1000</iyy>
            <iyz>0</iyz>
            <izz>1000</izz>
          </inertia>
        </inertial>
        <visual name="visual">
          <geometry>
            <mesh>
              <uri>model://submarine/resources/submarine.glb</uri>
            </mesh>
          </geometry>
        </visual>
        <collision name="collision">
          <geometry>
            <cylinder>
              <radius>1</radius>
              <length>2</length>
            </cylinder>
          </geometry>
        </collision>
      </link>

      <link name="propeller">
        <inertial>
          <mass>1e-6</mass>
        </inertial>
        <pose>-1.05 0 0 0 0 0</pose>
        <visual name="visual">
          <geometry>
            <box>
              <size>0.01 0.2 0.05</size>
            </box>
          </geometry>
        </visual>
      </link>

      <joint name="propeller_joint" type="revolute">
        <pose>0 0 0  0 3.14159265 0</pose>
        <parent>body</parent>
        <child>propeller</child>
        <axis>
          <xyz>-1 0 0</xyz>
          <limit>
            <lower>-1e+12</lower>
            <upper>1e+12</upper>
            <effort>-1</effort>
            <velocity>-1</velocity>
          </limit>
        </axis>
      </joint>

      <plugin
        filename="gz-sim-thruster-system"
        name="gz::sim::systems::Thruster">
        <joint_name>propeller_joint</joint_name>
        <thrust_coefficient>0.004</thrust_coefficient>
        <fluid_density>1000</fluid_density>
        <propeller_diameter>0.2</propeller_diameter>
        <max_thrust_cmd>300</max_thrust_cmd>
        <min_thrust_cmd>0</min_thrust_cmd>
      </plugin>

      <plugin
          filename="gz-sim-odometry-publisher-system"
          name="gz::sim::systems::OdometryPublisher">
      </plugin>

      <plugin
        filename="gz-sim-buoyancy-engine-system"
        name="gz::sim::systems::BuoyancyEngine">
        <link_name>body</link_name>
        <namespace>submarine</namespace>
        <min_volume>0.0</min_volume>
        <neutral_volume>0.002</neutral_volume>
        <default_volume>0.002</default_volume>
        <max_volume>0.003</max_volume>
        <max_inflation_rate>0.0003</max_inflation_rate>
      </plugin>

    </model>
</sdf>